<mujoco model="g1">
  <compiler angle="radian" meshdir="assets" autolimits="true"/>

  <option timestep="0.001" iterations="8" ls_iterations="4">
    <flag eulerdamp="disable"/>
  </option>

  <custom>
        <!-- brax custom params -->
        <numeric data="2500" name="constraint_limit_stiffness"/>
        <numeric data="27000" name="constraint_stiffness"/>
        <numeric data="30" name="constraint_ang_damping"/>
        <numeric data="80" name="constraint_vel_damping"/>
        <numeric data="-0.05" name="ang_damping"/>
        <numeric data="0.5" name="joint_scale_pos"/>
        <numeric data="0.1" name="joint_scale_ang"/>
        <numeric data="0" name="spring_mass_scale"/>
        <numeric data="1" name="spring_inertia_scale"/>
        <numeric data="20" name="matrix_inv_iterations"/>
        <numeric data="15" name="solver_maxls"/>
  </custom>


  <visual>
    <global ellipsoidinertia="true"/>
  </visual>

  <default>
    <geom contype="0" conaffinity="0" condim="3" solref="0.005 1"/>
    <equality solref="0.005 1"/>

    <default class="g1">
      <site rgba="1 0 0 1" size="0.01" group="5"/>
      <joint damping="0.5" armature="0.01" frictionloss="0.1"/>
      <default class="visual">
        <geom group="2" type="mesh" contype="0" conaffinity="0" density="0" material="metallic"/>
      </default>
      <default class="foot">
          <geom group="2" type="sphere" contype="0" conaffinity="0" density="0" size="0.01"/>
        </default>
      <default class="collision">
        <geom contype="1" group="3" type="sphere" rgba="0 0 0 0"/>
      </default>
    </default>
  </default>

  <asset>
    <material name="metallic" rgba="0.7 0.7 0.7 1"/>
    <material name="black" rgba="0.2 0.2 0.2 1"/>
    <material name="transparent" rgba="0 0 0 0"/>

    <mesh file="pelvis.STL"/>
    <mesh file="pelvis_contour_link.STL"/>
    <mesh file="left_hip_pitch_link.STL"/>
    <mesh file="left_hip_roll_link.STL"/>
    <mesh file="left_hip_yaw_link.STL"/>
    <mesh file="left_knee_link.STL"/>
    <mesh file="left_ankle_pitch_link.STL"/>
    <mesh file="left_ankle_roll_link.STL"/>
    <mesh file="right_hip_pitch_link.STL"/>
    <mesh file="right_hip_roll_link.STL"/>
    <mesh file="right_hip_yaw_link.STL"/>
    <mesh file="right_knee_link.STL"/>
    <mesh file="right_ankle_pitch_link.STL"/>
    <mesh file="right_ankle_roll_link.STL"/>
    <mesh file="torso_link.STL"/>
    <mesh file="head_link.STL"/>
    <mesh file="left_foot_simple.STL"/>
    <mesh file="right_foot_simple.STL"/>
  </asset>

  <worldbody>
    <light name="spotlight" mode="targetbodycom" target="pelvis" pos="0 -6 4" cutoff="30"/>
    <body name="pelvis" pos="0 0 0.755" childclass="g1">
      <site name="pelvis_back" pos="-0.05 0.0 0.0"/>
      <site name="pelvis_front" pos="0.05 0.0 0.0"/>
      <inertial pos="0 0 -0.07605" quat="1 0 -0.000405289 0" mass="2.86" diaginertia="0.0079143 0.0069837 0.0059404"/>
      <freejoint name="floating_base_joint"/>
      <light name="tracking" mode="trackcom" pos="0 0 2"/>
      <geom type="mesh" class="visual" mesh="pelvis"/>
      <geom type="mesh" class="visual" material="black" mesh="pelvis_contour_link"/>
      <body name="left_hip_pitch_link" pos="0 0.06445 -0.1027" quat="0.984807 0 -0.17365 0">
        <inertial pos="0.001962 0.049392 -0.000941" quat="0.420735 0.907025 -0.0155675 -0.00670646" mass="1.299"
          diaginertia="0.00138785 0.000955478 0.00086947"/>
        <joint name="left_hip_pitch_joint" axis="0 1 0" range="-2.35 3.05"/>
        <geom type="mesh" class="visual" material="black" mesh="left_hip_pitch_link"/>
        <body name="left_hip_roll_link" pos="0 0.0523 0">
          <inertial pos="0.024757 -0.001036 -0.086323" quat="0.977498 -0.00692636 0.210181 0.0165269" mass="1.446"
            diaginertia="0.00244106 0.00230425 0.00142899"/>
          <joint name="left_hip_roll_joint" axis="1 0 0" range="-0.26 2.53"/>
          <geom type="mesh" class="visual" mesh="left_hip_roll_link"/>
          <body name="left_hip_yaw_link" pos="0.01966 -0.0012139 -0.1241">
            <inertial pos="-0.053554 -0.011477 -0.14067" quat="0.645099 0.15885 0.202109 0.71956" mass="2.052"
              diaginertia="0.0114475 0.0107868 0.00214501"/>
            <joint name="left_hip_yaw_joint" axis="0 0 1" range="-2.75 2.75"/>
            <geom type="mesh" class="visual" mesh="left_hip_yaw_link"/>
            <body name="left_knee_link" pos="-0.078292 -0.0017335 -0.177225" quat="0.967714 0 0.252052 0">
              <inertial pos="0.005505 0.006534 -0.116629" quat="0.799234 -0.0128894 0.0354278 0.599836" mass="2.252"
                diaginertia="0.0127418 0.0124382 0.00192524"/>
              <joint name="left_knee_joint" axis="0 1 0" range="-0.33489 2.5449"/>
              <geom type="mesh" class="visual" mesh="left_knee_link"/>
              <body name="left_ankle_pitch_link" pos="0 0.0040687 -0.30007" quat="0.99678 0 -0.0801788 0">
                <inertial pos="-0.007269 0 0.011137" quat="0.603053 0.369225 0.369225 0.603053" mass="0.074"
                  diaginertia="1.89e-05 1.40805e-05 6.9195e-06"/>
                <joint name="left_ankle_pitch_joint" axis="0 1 0" range="-0.68 0.73"/>
                <geom type="mesh" class="visual" mesh="left_ankle_pitch_link"/>
                <body name="left_ankle_roll_link" pos="0 0 -0.017558">
                  <site name="left_foot_p1" pos="0.05 0.0 -0.034"/>
                  <site name="left_foot_p2" pos="-0.05 0.0 -0.034"/>
                  <site name="left_foot_p3" pos="0.0 0.05 -0.034"/>
                  <inertial pos="0.024762 2e-05 -0.012526" quat="0.000771333 0.734476 0.000921291 0.678634" mass="0.391"
                    diaginertia="0.00110394 0.0010657 0.000149255"/>
                  <joint name="left_ankle_roll_joint" axis="1 0 0" range="-0.2618 0.2618"/>
                  <geom type="mesh" class="visual" material="black" mesh="left_ankle_roll_link"/>
                  <geom type="mesh" mesh="left_foot_simple" class="collision" name="left_foot" rgba="1 1 1 0"/>
                  <geom pos="-0.06 0.02 -0.03" class="foot"/>
                  <geom pos="-0.06 -0.02 -0.03" class="foot"/>
                  <geom pos="0.13 0.02 -0.03" class="foot"/>
                  <geom pos="0.13 -0.02 -0.03" class="foot"/>
                </body>
              </body>
            </body>
          </body>
        </body>
      </body>
      <body name="right_hip_pitch_link" pos="0 -0.06445 -0.1027" quat="0.984807 0 -0.17365 0">
        <inertial pos="0.001962 -0.049392 -0.000941" quat="0.907025 0.420735 0.00670646 0.0155675" mass="1.299"
          diaginertia="0.00138785 0.000955478 0.00086947"/>
        <joint name="right_hip_pitch_joint" axis="0 1 0" range="-2.35 3.05"/>
        <geom type="mesh" class="visual" material="black" mesh="right_hip_pitch_link"/>
        <body name="right_hip_roll_link" pos="0 -0.0523 0">
          <inertial pos="0.024757 0.001036 -0.086323" quat="0.977498 0.00692636 0.210181 -0.0165269" mass="1.446"
            diaginertia="0.00244106 0.00230425 0.00142899"/>
          <joint name="right_hip_roll_joint" axis="1 0 0" range="-2.53 0.26"/>
          <geom type="mesh" class="visual" mesh="right_hip_roll_link"/>
          <body name="right_hip_yaw_link" pos="0.01966 0.0012139 -0.1241">
            <inertial pos="-0.053554 0.011477 -0.14067" quat="0.71956 0.202109 0.15885 0.645099" mass="2.052"
              diaginertia="0.0114475 0.0107868 0.00214501"/>
            <joint name="right_hip_yaw_joint" axis="0 0 1" range="-2.75 2.75"/>
            <geom type="mesh" class="visual" mesh="right_hip_yaw_link"/>
            <body name="right_knee_link" pos="-0.078292 0.0017335 -0.177225" quat="0.967714 0 0.252052 0">
              <inertial pos="0.005505 -0.006534 -0.116629" quat="0.599836 0.0354278 -0.0128894 0.799234" mass="2.252"
                diaginertia="0.0127418 0.0124382 0.00192524"/>
              <joint name="right_knee_joint" axis="0 1 0" range="-0.33489 2.5449"/>
              <geom type="mesh" class="visual" mesh="right_knee_link"/>
              <body name="right_ankle_pitch_link" pos="0 -0.0040687 -0.30007" quat="0.99678 0 -0.0801788 0">
                <inertial pos="-0.007269 0 0.011137" quat="0.603053 0.369225 0.369225 0.603053" mass="0.074"
                  diaginertia="1.89e-05 1.40805e-05 6.9195e-06"/>
                <joint name="right_ankle_pitch_joint" axis="0 1 0" range="-0.68 0.73"/>
                <geom type="mesh" class="visual" mesh="right_ankle_pitch_link"/>
                <body name="right_ankle_roll_link" pos="0 0 -0.017558">
                  <site name="right_foot_p1" pos="0.05 0.0 -0.034"/>
                  <site name="right_foot_p2" pos="-0.05 0.0 -0.034"/>
                  <site name="right_foot_p3" pos="0.0 -0.05 -0.034"/>
                  <inertial pos="0.024762 -2e-05 -0.012526" quat="-0.000771333 0.734476 -0.000921291 0.678634"
                    mass="0.391" diaginertia="0.00110394 0.0010657 0.000149255"/>
                  <joint name="right_ankle_roll_joint" axis="1 0 0" range="-0.2618 0.2618"/>
                  <geom type="mesh" class="visual" material="black" mesh="right_ankle_roll_link"/>
                  <geom type="mesh" mesh="right_foot_simple" class="collision" name="right_foot" rgba="0 0 0 0"/>
                  <geom pos="-0.06 0.02 -0.03" class="foot"/>
                  <geom pos="-0.06 -0.02 -0.03" class="foot"/>
                  <geom pos="0.13 0.02 -0.03" class="foot"/>
                  <geom pos="0.13 -0.02 -0.03" class="foot"/>
                </body>
              </body>
            </body>
          </body>
        </body>
      </body>
      <body name="torso_link">
        <inertial pos="0.00187791 0.00229457 0.208747" quat="0.999957 0.00624375 -0.00636707 -0.0026338" mass="7.52036"
          diaginertia="0.12848 0.111753 0.0350394"/>
        <site name="imu" pos="-0.04233868314 0.00166 0.152067"/>
        <site name="head" pos="0 0 0.5"/>
        <joint name="torso_joint" axis="0 0 1" range="-2.618 2.618"/>
        <geom type="mesh" class="visual" mesh="torso_link"/>
        <geom type="mesh" class="visual" material="black" mesh="head_link"/>
      </body>
    </body>
  </worldbody>

  <actuator>
    <position kp="400.0" class="g1" name="left_hip_pitch_joint" joint="left_hip_pitch_joint" forcerange="-88 88" inheritrange="1"/>
    <position kp="400.0" class="g1" name="left_hip_roll_joint" joint="left_hip_roll_joint" forcerange="-88 88" inheritrange="1"/>
    <position kp="400.0" class="g1" name="left_hip_yaw_joint" joint="left_hip_yaw_joint" forcerange="-88 88" inheritrange="1"/>
    <position kp="400.0" class="g1" name="left_knee_joint" joint="left_knee_joint" forcerange="-139 139" inheritrange="1"/>
    <position kp="400.0" class="g1" name="left_ankle_pitch_joint" joint="left_ankle_pitch_joint" forcerange="-40 40" inheritrange="1"/>
    <position kp="400.0" class="g1" name="left_ankle_roll_joint" joint="left_ankle_roll_joint" forcerange="-40 40" inheritrange="1"/>

    <position kp="400.0" class="g1" name="right_hip_pitch_joint" joint="right_hip_pitch_joint" forcerange="-88 88" inheritrange="1"/>
    <position kp="400.0" class="g1" name="right_hip_roll_joint" joint="right_hip_roll_joint" forcerange="-88 88" inheritrange="1"/>
    <position kp="400.0" class="g1" name="right_hip_yaw_joint" joint="right_hip_yaw_joint" forcerange="-88 88" inheritrange="1"/>
    <position kp="400.0" class="g1" name="right_knee_joint" joint="right_knee_joint" forcerange="-139 139" inheritrange="1"/>
    <position kp="400.0" class="g1" name="right_ankle_pitch_joint" joint="right_ankle_pitch_joint" forcerange="-40 40" inheritrange="1"/>
    <position kp="400.0" class="g1" name="right_ankle_roll_joint" joint="right_ankle_roll_joint" forcerange="-40 40" inheritrange="1"/>

    <position kp="400.0" class="g1" name="torso_joint" joint="torso_joint" forcerange="-88 88" inheritrange="1"/>

    <velocity kv="40.0" class="g1" name="left_hip_pitch_joint_v" joint="left_hip_pitch_joint" forcerange="-88 88" ctrlrange="-10 10"/>
    <velocity kv="40.0" class="g1" name="left_hip_roll_joint_v" joint="left_hip_roll_joint" forcerange="-88 88" ctrlrange="-10 10"/>
    <velocity kv="40.0" class="g1" name="left_hip_yaw_joint_v" joint="left_hip_yaw_joint" forcerange="-88 88" ctrlrange="-10 10"/>
    <velocity kv="40.0" class="g1" name="left_knee_joint_v" joint="left_knee_joint" forcerange="-139 139" ctrlrange="-10 10"/>
    <velocity kv="40.0" class="g1" name="left_ankle_pitch_joint_v" joint="left_ankle_pitch_joint" forcerange="-40 40" ctrlrange="-10 10"/>
    <velocity kv="40.0" class="g1" name="left_ankle_roll_joint_v" joint="left_ankle_roll_joint" forcerange="-40 40" ctrlrange="-10 10"/>

    <velocity kv="40.0" class="g1" name="right_hip_pitch_joint_v" joint="right_hip_pitch_joint" forcerange="-88 88" ctrlrange="-10 10"/>
    <velocity kv="40.0" class="g1" name="right_hip_roll_joint_v" joint="right_hip_roll_joint" forcerange="-88 88" ctrlrange="-10 10"/>
    <velocity kv="40.0" class="g1" name="right_hip_yaw_joint_v" joint="right_hip_yaw_joint" forcerange="-88 88" ctrlrange="-10 10"/>
    <velocity kv="40.0" class="g1" name="right_knee_joint_v" joint="right_knee_joint" forcerange="-139 139" ctrlrange="-10 10"/>
    <velocity kv="40.0" class="g1" name="right_ankle_pitch_joint_v" joint="right_ankle_pitch_joint" forcerange="-40 40" ctrlrange="-10 10"/>
    <velocity kv="40.0" class="g1" name="right_ankle_roll_joint_v" joint="right_ankle_roll_joint" forcerange="-40 40" ctrlrange="-10 10"/>

    <velocity kv="40.0" class="g1" name="torso_joint_v" joint="torso_joint" forcerange="-88 88" ctrlrange="-10 10"/>
  </actuator>

  <sensor>
    <gyro name="imu-angular-velocity" site="imu" cutoff="34.9"/>
    <accelerometer name="imu-linear-acceleration" site="imu" cutoff="157"/>
    <framequat name="imu-body-quat" objtype="site" objname="imu"/>
  </sensor>

  <keyframe>
    <key name="stand"
      qpos="
      0 0 0.75
      1 0 0 0
      0 0 0 0 0 0
      0 0 0 0 0 0
      0"/>
  </keyframe>
</mujoco>
