<?xml version="1.0" ?>
<robot name="converted_robot">
   <!--generated with mjcf_urdf_simple_converter (https://github.com/Yasu31/mjcf_urdf_simple_converter)-->
   <link name="world">
      <inertial>
         <origin xyz="0.0 0.0 0.0" rpy="0.0 0.0 0.0"/>
         <mass value="0.0"/>
         <inertia ixx="0.0" iyy="0.0" izz="0.0" ixy="0" ixz="0" iyz="0"/>
      </inertial>
   </link>
   <link name="pelvis">
      <inertial>
         <origin xyz="0.0 0.0 0.2" rpy="0.0 0.0 0.0"/>
         <mass value="5.11537484"/>
         <inertia ixx="0.03" iyy="0.03" izz="0.03" ixy="0" ixz="0" iyz="0"/>
      </inertial>
      <visual name="pelvis">
         <origin xyz="2.47764632813843e-09 1.7056346093980415e-08 -0.0628889958727471" rpy="1.5707963267948966 0.0 0.0"/>
         <geometry>
            <mesh filename="converted_pelvis.stl"/>
         </geometry>
         <material name="white"/>
      </visual>
   </link>
   <link name="floating_base_jointbody">
      <inertial>
         <origin xyz="0.0 0.0 0.0" rpy="0.0 0.0 0.0"/>
         <mass value="0.001"/>
         <inertia ixx="1e-09" iyy="1e-09" izz="1e-09" ixy="0" ixz="0" iyz="0"/>
      </inertial>
   </link>
   <joint type="fixed" name="floating_base">
      <parent link="world"/>
      <child link="floating_base_jointbody"/>
      <origin xyz="0.0 0.0 0.6088" rpy="0.0 0.0 0.0"/>
   </joint>
   <joint type="fixed" name="floating_base_offset">
      <parent link="floating_base_jointbody"/>
      <child link="pelvis"/>
      <origin xyz="-0.0 -0.0 -0.0" rpy="0.0 0.0 0.0"/>
   </joint>
   <link name="l_hip_pitch">
      <inertial>
         <origin xyz="-0.01821923 -0.0 -3.205e-05" rpy="1.569617007170609 -4.169155001454428e-06 1.57100088478941"/>
         <mass value="1.8670971"/>
         <inertia ixx="0.003633570040911599" iyy="0.0035800912854579733" izz="0.0026558286736304273" ixy="0" ixz="0" iyz="0"/>
      </inertial>
      <visual name="l_hip_pitch">
         <origin xyz="-0.016426052318942425 3.8693881999687e-07 -6.069910635333717e-06" rpy="1.5710456119730067 0.0002896989381866444 1.570802668524427"/>
         <geometry>
            <mesh filename="converted_l_hip_pitch.stl"/>
         </geometry>
         <material name="white"/>
      </visual>
   </link>
   <link name="l_hip_pitch_jointbody">
      <inertial>
         <origin xyz="0.0 0.0 0.0" rpy="0.0 0.0 0.0"/>
         <mass value="0.001"/>
         <inertia ixx="1e-09" iyy="1e-09" izz="1e-09" ixy="0" ixz="0" iyz="0"/>
      </inertial>
   </link>
   <joint type="revolute" name="l_hip_pitch">
      <parent link="pelvis"/>
      <child link="l_hip_pitch_jointbody"/>
      <origin xyz="0.0 0.0965 -0.112" rpy="0.0 0.0 0.0"/>
      <axis xyz="0.0 1.0 0.0"/>
      <limit lower="-1.3" upper="1.3" effort="100" velocity="100"/>
   </joint>
   <joint type="fixed" name="l_hip_pitch_offset">
      <parent link="l_hip_pitch_jointbody"/>
      <child link="l_hip_pitch"/>
      <origin xyz="-0.0 -0.0 -0.0" rpy="0.0 0.0 0.0"/>
   </joint>
   <link name="l_hip_roll">
      <inertial>
         <origin xyz="-0.01740501 1.764e-05 -0.05845559" rpy="0.0004863223254489439 0.19610377555273417 0.0010392456801208367"/>
         <mass value="2.00459959"/>
         <inertia ixx="0.006611571483374219" iyy="0.006331359985392611" izz="0.0028985185312331704" ixy="0" ixz="0" iyz="0"/>
      </inertial>
      <visual name="l_hip_roll">
         <origin xyz="-0.01736573595523465 2.8464927243536956e-06 -0.05970583053459872" rpy="0.00014232068753268503 -0.18267748790935934 -0.0003902767213758727"/>
         <geometry>
            <mesh filename="converted_l_hip_roll.stl"/>
         </geometry>
         <material name="white"/>
      </visual>
   </link>
   <link name="l_hip_roll_jointbody">
      <inertial>
         <origin xyz="0.0 0.0 0.0" rpy="0.0 0.0 0.0"/>
         <mass value="0.001"/>
         <inertia ixx="1e-09" iyy="1e-09" izz="1e-09" ixy="0" ixz="0" iyz="0"/>
      </inertial>
   </link>
   <joint type="revolute" name="l_hip_roll">
      <parent link="l_hip_pitch"/>
      <child link="l_hip_roll_jointbody"/>
      <origin xyz="-0.07875 0.0 0.0" rpy="0.0 0.0 0.0"/>
      <axis xyz="1.0 0.0 0.0"/>
      <limit lower="-0.4" upper="1.5" effort="100" velocity="100"/>
   </joint>
   <joint type="fixed" name="l_hip_roll_offset">
      <parent link="l_hip_roll_jointbody"/>
      <child link="l_hip_roll"/>
      <origin xyz="-0.0 -0.0 -0.0" rpy="0.0 0.0 0.0"/>
   </joint>
   <link name="l_hip_yaw">
      <inertial>
         <origin xyz="3.205e-05 -0.0 -0.06053076999999999" rpy="0.001179318771453497 0.0002045579945115783 1.5707921576398078"/>
         <mass value="1.8670971"/>
         <inertia ixx="0.003633570040911599" iyy="0.0035800912854579733" izz="0.0026558286736304273" ixy="0" ixz="0" iyz="0"/>
      </inertial>
      <visual name="l_hip_yaw">
         <origin xyz="5.83664874371905e-06 1.7109240304756822e-06 -0.062326293981562565" rpy="-0.0002696017728186506 0.00016457134354230796 1.5707920334258687"/>
         <geometry>
            <mesh filename="converted_l_hip_yaw.stl"/>
         </geometry>
         <material name="white"/>
      </visual>
   </link>
   <link name="l_hip_yaw_jointbody">
      <inertial>
         <origin xyz="0.0 0.0 0.0" rpy="0.0 0.0 0.0"/>
         <mass value="0.001"/>
         <inertia ixx="1e-09" iyy="1e-09" izz="1e-09" ixy="0" ixz="0" iyz="0"/>
      </inertial>
   </link>
   <joint type="revolute" name="l_hip_yaw">
      <parent link="l_hip_roll"/>
      <child link="l_hip_yaw_jointbody"/>
      <origin xyz="0.00715 0.0 -0.1263" rpy="0.0 0.0 0.0"/>
      <axis xyz="0.0 0.0 1.0"/>
      <limit lower="-1.0" upper="1.0" effort="100" velocity="100"/>
   </joint>
   <joint type="fixed" name="l_hip_yaw_offset">
      <parent link="l_hip_yaw_jointbody"/>
      <child link="l_hip_yaw"/>
      <origin xyz="-0.0 -0.0 -0.0" rpy="0.0 0.0 0.0"/>
   </joint>
   <link name="l_knee">
      <inertial>
         <origin xyz="0.0 5e-05 -0.10289321" rpy="0.0 0.0 0.0"/>
         <mass value="0.58007416"/>
         <inertia ixx="0.0070466" iyy="0.00513742" izz="0.00225232" ixy="0" ixz="0" iyz="0"/>
      </inertial>
      <visual name="l_knee">
         <origin xyz="-1.4921539788234289e-09 7.910392518134238e-09 -0.10297404194441043" rpy="0.0 0.0 -3.2172707848725117e-06"/>
         <geometry>
            <mesh filename="converted_l_knee.stl"/>
         </geometry>
         <material name="white"/>
      </visual>
   </link>
   <link name="l_knee_jointbody">
      <inertial>
         <origin xyz="0.0 0.0 0.0" rpy="0.0 0.0 0.0"/>
         <mass value="0.001"/>
         <inertia ixx="1e-09" iyy="1e-09" izz="1e-09" ixy="0" ixz="0" iyz="0"/>
      </inertial>
   </link>
   <joint type="revolute" name="l_knee">
      <parent link="l_hip_yaw"/>
      <child link="l_knee_jointbody"/>
      <origin xyz="0.0 0.0 -0.07875" rpy="0.0 0.0 0.0"/>
      <axis xyz="0.0 1.0 0.0"/>
      <limit lower="-2.0" upper="2.0" effort="100" velocity="100"/>
   </joint>
   <joint type="fixed" name="l_knee_offset">
      <parent link="l_knee_jointbody"/>
      <child link="l_knee"/>
      <origin xyz="-0.0 -0.0 -0.0" rpy="0.0 0.0 0.0"/>
   </joint>
   <link name="l_foot_pitch">
      <inertial>
         <origin xyz="0.01821923 -0.0 -3.205e-05" rpy="1.571975646419184 4.169155001454428e-06 1.57100088478941"/>
         <mass value="1.8670971"/>
         <inertia ixx="0.003633570040911599" iyy="0.0035800912854579733" izz="0.0026558286736304273" ixy="0" ixz="0" iyz="0"/>
      </inertial>
      <visual name="l_foot_pitch">
         <origin xyz="0.01642265215060797 -2.5247692832924115e-06 -6.3433757846142034e-06" rpy="1.5705709613898433 -2.2427544625447382e-05 1.5706413297236463"/>
         <geometry>
            <mesh filename="converted_l_foot_pitch.stl"/>
         </geometry>
         <material name="white"/>
      </visual>
   </link>
   <link name="l_foot_pitch_jointbody">
      <inertial>
         <origin xyz="0.0 0.0 0.0" rpy="0.0 0.0 0.0"/>
         <mass value="0.001"/>
         <inertia ixx="1e-09" iyy="1e-09" izz="1e-09" ixy="0" ixz="0" iyz="0"/>
      </inertial>
   </link>
   <joint type="revolute" name="l_foot_pitch">
      <parent link="l_knee"/>
      <child link="l_foot_pitch_jointbody"/>
      <origin xyz="0.0 0.0 -0.206" rpy="0.0 0.0 0.0"/>
      <axis xyz="0.0 1.0 0.0"/>
      <limit lower="-2.0" upper="2.0" effort="100" velocity="100"/>
   </joint>
   <joint type="fixed" name="l_foot_pitch_offset">
      <parent link="l_foot_pitch_jointbody"/>
      <child link="l_foot_pitch"/>
      <origin xyz="-0.0 -0.0 -0.0" rpy="0.0 0.0 0.0"/>
   </joint>
   <link name="l_foot_roll">
      <inertial>
         <origin xyz="0.00757956 1.139e-05 -0.03942379" rpy="2.3433878067998437 -0.0008879622578734647 1.569836156558178"/>
         <mass value="1.5526793"/>
         <inertia ixx="0.005416700784880941" iyy="0.004963623876621819" izz="0.0028013153384972476" ixy="0" ixz="0" iyz="0"/>
      </inertial>
      <visual name="l_foot_roll">
         <origin xyz="0.007994183510704024 1.1742462541293414e-05 -0.03811882374488236" rpy="0.805359327591217 -0.00015554951913299142 1.5712645041576923"/>
         <geometry>
            <mesh filename="converted_l_foot_roll.stl"/>
         </geometry>
         <material name="white"/>
      </visual>
   </link>
   <link name="l_foot_roll_jointbody">
      <inertial>
         <origin xyz="0.0 0.0 0.0" rpy="0.0 0.0 0.0"/>
         <mass value="0.001"/>
         <inertia ixx="1e-09" iyy="1e-09" izz="1e-09" ixy="0" ixz="0" iyz="0"/>
      </inertial>
   </link>
   <joint type="revolute" name="l_foot_roll">
      <parent link="l_foot_pitch"/>
      <child link="l_foot_roll_jointbody"/>
      <origin xyz="0.07875 0.0 0.0" rpy="0.0 0.0 0.0"/>
      <axis xyz="1.0 0.0 0.0"/>
      <limit lower="-1.0" upper="1.0" effort="100" velocity="100"/>
   </joint>
   <joint type="fixed" name="l_foot_roll_offset">
      <parent link="l_foot_roll_jointbody"/>
      <child link="l_foot_roll"/>
      <origin xyz="-0.0 -0.0 -0.0" rpy="0.0 0.0 0.0"/>
   </joint>
   <link name="r_hip_pitch">
      <inertial>
         <origin xyz="-0.01821923 -0.0 -3.205e-05" rpy="1.569617007170609 -4.169155001454428e-06 1.57100088478941"/>
         <mass value="1.8670971"/>
         <inertia ixx="0.003633570040911599" iyy="0.0035800912854579733" izz="0.0026558286736304273" ixy="0" ixz="0" iyz="0"/>
      </inertial>
      <visual name="r_hip_pitch">
         <origin xyz="-0.016426052311187045 -3.8697664800539455e-07 -6.069910157291952e-06" rpy="1.571045608706061 -0.0002897102791530326 1.5707899781964318"/>
         <geometry>
            <mesh filename="converted_r_hip_pitch.stl"/>
         </geometry>
         <material name="white"/>
      </visual>
   </link>
   <link name="r_hip_pitch_jointbody">
      <inertial>
         <origin xyz="0.0 0.0 0.0" rpy="0.0 0.0 0.0"/>
         <mass value="0.001"/>
         <inertia ixx="1e-09" iyy="1e-09" izz="1e-09" ixy="0" ixz="0" iyz="0"/>
      </inertial>
   </link>
   <joint type="revolute" name="r_hip_pitch">
      <parent link="pelvis"/>
      <child link="r_hip_pitch_jointbody"/>
      <origin xyz="0.0 -0.0965 -0.112" rpy="0.0 0.0 0.0"/>
      <axis xyz="0.0 1.0 0.0"/>
      <limit lower="-1.3" upper="1.3" effort="100" velocity="100"/>
   </joint>
   <joint type="fixed" name="r_hip_pitch_offset">
      <parent link="r_hip_pitch_jointbody"/>
      <child link="r_hip_pitch"/>
      <origin xyz="-0.0 -0.0 -0.0" rpy="0.0 0.0 0.0"/>
   </joint>
   <link name="r_hip_roll">
      <inertial>
         <origin xyz="-0.01740501 1.764e-05 -0.05845559" rpy="0.0004863223254489439 0.19610377555273417 0.0010392456801208367"/>
         <mass value="2.00459959"/>
         <inertia ixx="0.006611571483374219" iyy="0.006331359985392611" izz="0.0028985185312331704" ixy="0" ixz="0" iyz="0"/>
      </inertial>
      <visual name="r_hip_roll">
         <origin xyz="-0.01736573590596694 -2.846560797212238e-06 -0.059705830517740546" rpy="-0.0001423206363125254 -0.18267748889084268 0.0003902816912764815"/>
         <geometry>
            <mesh filename="converted_r_hip_roll.stl"/>
         </geometry>
         <material name="white"/>
      </visual>
   </link>
   <link name="r_hip_roll_jointbody">
      <inertial>
         <origin xyz="0.0 0.0 0.0" rpy="0.0 0.0 0.0"/>
         <mass value="0.001"/>
         <inertia ixx="1e-09" iyy="1e-09" izz="1e-09" ixy="0" ixz="0" iyz="0"/>
      </inertial>
   </link>
   <joint type="revolute" name="r_hip_roll">
      <parent link="r_hip_pitch"/>
      <child link="r_hip_roll_jointbody"/>
      <origin xyz="-0.07875 0.0 0.0" rpy="0.0 0.0 0.0"/>
      <axis xyz="1.0 0.0 0.0"/>
      <limit lower="-1.5" upper="0.4" effort="100" velocity="100"/>
   </joint>
   <joint type="fixed" name="r_hip_roll_offset">
      <parent link="r_hip_roll_jointbody"/>
      <child link="r_hip_roll"/>
      <origin xyz="-0.0 -0.0 -0.0" rpy="0.0 0.0 0.0"/>
   </joint>
   <link name="r_hip_yaw">
      <inertial>
         <origin xyz="3.205e-05 -0.0 -0.06053076999999999" rpy="0.001179318771453497 0.0002045579945115783 1.5707921576398078"/>
         <mass value="1.8670971"/>
         <inertia ixx="0.003633570040911599" iyy="0.0035800912854579733" izz="0.0026558286736304273" ixy="0" ixz="0" iyz="0"/>
      </inertial>
      <visual name="r_hip_yaw">
         <origin xyz="5.8366539332816436e-06 -1.7109134866172812e-06 -0.06232629396045607" rpy="-0.00026959739179754916 -0.0001645742933347183 1.5708006286735454"/>
         <geometry>
            <mesh filename="converted_r_hip_yaw.stl"/>
         </geometry>
         <material name="white"/>
      </visual>
   </link>
   <link name="r_hip_yaw_jointbody">
      <inertial>
         <origin xyz="0.0 0.0 0.0" rpy="0.0 0.0 0.0"/>
         <mass value="0.001"/>
         <inertia ixx="1e-09" iyy="1e-09" izz="1e-09" ixy="0" ixz="0" iyz="0"/>
      </inertial>
   </link>
   <joint type="revolute" name="r_hip_yaw">
      <parent link="r_hip_roll"/>
      <child link="r_hip_yaw_jointbody"/>
      <origin xyz="0.00715 0.0 -0.1263" rpy="0.0 0.0 0.0"/>
      <axis xyz="0.0 0.0 1.0"/>
      <limit lower="-1.0" upper="1.0" effort="100" velocity="100"/>
   </joint>
   <joint type="fixed" name="r_hip_yaw_offset">
      <parent link="r_hip_yaw_jointbody"/>
      <child link="r_hip_yaw"/>
      <origin xyz="-0.0 -0.0 -0.0" rpy="0.0 0.0 0.0"/>
   </joint>
   <link name="r_knee">
      <inertial>
         <origin xyz="0.0 5e-05 -0.10289321" rpy="0.0 0.0 0.0"/>
         <mass value="0.58007416"/>
         <inertia ixx="0.0070466" iyy="0.00513742" izz="0.00225232" ixy="0" ixz="0" iyz="0"/>
      </inertial>
      <visual name="l_knee">
         <origin xyz="-1.4921539788234289e-09 7.910392518134238e-09 -0.10297404194441043" rpy="0.0 0.0 -3.2172707848725117e-06"/>
         <geometry>
            <mesh filename="converted_l_knee.stl"/>
         </geometry>
         <material name="white"/>
      </visual>
   </link>
   <link name="r_knee_jointbody">
      <inertial>
         <origin xyz="0.0 0.0 0.0" rpy="0.0 0.0 0.0"/>
         <mass value="0.001"/>
         <inertia ixx="1e-09" iyy="1e-09" izz="1e-09" ixy="0" ixz="0" iyz="0"/>
      </inertial>
   </link>
   <joint type="revolute" name="r_knee">
      <parent link="r_hip_yaw"/>
      <child link="r_knee_jointbody"/>
      <origin xyz="0.0 0.0 -0.07875" rpy="0.0 0.0 0.0"/>
      <axis xyz="0.0 1.0 0.0"/>
      <limit lower="-2.0" upper="2.0" effort="100" velocity="100"/>
   </joint>
   <joint type="fixed" name="r_knee_offset">
      <parent link="r_knee_jointbody"/>
      <child link="r_knee"/>
      <origin xyz="-0.0 -0.0 -0.0" rpy="0.0 0.0 0.0"/>
   </joint>
   <link name="r_foot_pitch">
      <inertial>
         <origin xyz="0.01821923 -0.0 -3.205e-05" rpy="1.571975646419184 4.169155001454428e-06 1.57100088478941"/>
         <mass value="1.8670971"/>
         <inertia ixx="0.003633570040911599" iyy="0.0035800912854579733" izz="0.0026558286736304273" ixy="0" ixz="0" iyz="0"/>
      </inertial>
      <visual name="l_foot_pitch">
         <origin xyz="0.01642265215060797 -2.5247692832924115e-06 -6.3433757846142034e-06" rpy="1.5705709613898433 -2.2427544625447382e-05 1.5706413297236463"/>
         <geometry>
            <mesh filename="converted_l_foot_pitch.stl"/>
         </geometry>
         <material name="white"/>
      </visual>
   </link>
   <link name="r_foot_pitch_jointbody">
      <inertial>
         <origin xyz="0.0 0.0 0.0" rpy="0.0 0.0 0.0"/>
         <mass value="0.001"/>
         <inertia ixx="1e-09" iyy="1e-09" izz="1e-09" ixy="0" ixz="0" iyz="0"/>
      </inertial>
   </link>
   <joint type="revolute" name="r_foot_pitch">
      <parent link="r_knee"/>
      <child link="r_foot_pitch_jointbody"/>
      <origin xyz="0.0 0.0 -0.206" rpy="0.0 0.0 0.0"/>
      <axis xyz="0.0 1.0 0.0"/>
      <limit lower="-2.0" upper="2.0" effort="100" velocity="100"/>
   </joint>
   <joint type="fixed" name="r_foot_pitch_offset">
      <parent link="r_foot_pitch_jointbody"/>
      <child link="r_foot_pitch"/>
      <origin xyz="-0.0 -0.0 -0.0" rpy="0.0 0.0 0.0"/>
   </joint>
   <link name="r_foot_roll">
      <inertial>
         <origin xyz="0.00757956 1.139e-05 -0.03942379" rpy="2.3433878067998437 -0.0008879622578734647 1.569836156558178"/>
         <mass value="1.5526793"/>
         <inertia ixx="0.005416700784880941" iyy="0.004963623876621819" izz="0.0028013153384972476" ixy="0" ixz="0" iyz="0"/>
      </inertial>
      <visual name="l_foot_roll">
         <origin xyz="0.007994183510704024 1.1742462541293414e-05 -0.03811882374488236" rpy="0.805359327591217 -0.00015554951913299142 1.5712645041576923"/>
         <geometry>
            <mesh filename="converted_l_foot_roll.stl"/>
         </geometry>
         <material name="white"/>
      </visual>
   </link>
   <link name="r_foot_roll_jointbody">
      <inertial>
         <origin xyz="0.0 0.0 0.0" rpy="0.0 0.0 0.0"/>
         <mass value="0.001"/>
         <inertia ixx="1e-09" iyy="1e-09" izz="1e-09" ixy="0" ixz="0" iyz="0"/>
      </inertial>
   </link>
   <joint type="revolute" name="r_foot_roll">
      <parent link="r_foot_pitch"/>
      <child link="r_foot_roll_jointbody"/>
      <origin xyz="0.07875 0.0 0.0" rpy="0.0 0.0 0.0"/>
      <axis xyz="1.0 0.0 0.0"/>
      <limit lower="-1.0" upper="1.0" effort="100" velocity="100"/>
   </joint>
   <joint type="fixed" name="r_foot_roll_offset">
      <parent link="r_foot_roll_jointbody"/>
      <child link="r_foot_roll"/>
      <origin xyz="-0.0 -0.0 -0.0" rpy="0.0 0.0 0.0"/>
   </joint>
   <material name="white">
      <color rgba="1 1 1 1"/>
   </material>
</robot>
